표준 예외 처리 클래스 : RuntimeException, IllegalArgumentException, IllegalStateException, NoSuchElementException

함수에서 throw로 예외를 던질 수 있음
함수를 호출하는 쪽에서 예외를 catch하여 처리 가능

try, catch, finally 구문 이용

Exception은 처리하고 Error는 심각한 오류이므로 처리 없이 Error를 내는 것이 권장됨.

- - -
runCatching과 Result 활용하기
```kotlin
@InlineOnly  
@SinceKotlin("1.3")  
public inline fun <R> runCatching(block: () -> R): Result<R> {  
    return try {  
        Result.success(block())  
    } catch (e: Throwable) {  
        Result.failure(e)  
    }  
}
```
내부에 try-catch 구문을 사용한다.
단지 Result(.success, .failure)로 값을 반환하는데 Result<\T>와 Result<Failure<\exception>> 값.

우테코 프리코스 3주차 미션 중 값을 잘못 입력 받을 시, 계속 다시 입력을 받아야 했음.
예외 테스트에서 `no line found` 무한루프 발생.

```kotlin
// 초기에 짠 코드 - 테스트코드가 입력 값을 계속 제공하지 않기 때문에 무한 루프 에러
inline fun <T> safeInputCall(block: () -> T): T {
	while(true) {
		return runCatching(block).onFailure { e -> 
			println(e.message) 
		}.getOrNull() ?: continue
	}
}

// while-try-catch 구문으로는 이상 없었음
while (true) {  
    try {  
        val input = read()  
        val price = input.toIntOrException()  
  
        validator.validatePriceRange(price)  
        validator.validatePriceRange(price)  
  
        return price  
    } catch (e: IllegalArgumentException) {  
        println(e.message)  
    }  
}
```

문제가 된 것은 try-catch의 catch 구문도 throwable을 받지만 어떤 에러를 잡을지 결정하기에 하위 Exception을 선언할 수 있다. runCatching의 failure는 block이 실패했을 때 Throwable을 받기 때문에 클래스 그대로 e가 들어가게 된다. 즉, e가 처리할 exception인지 또 검사해주어야 한다.
ps. Throwable 객체는 Error와 Exception의 최상위 클래스.

```kotlin
inline fun <T> safeInputCall(block: () -> T): T {  
    while(true) {  
        return runCatching(block).onFailure { e: Throwable ->  
            if(e is IllegalArgumentException) println(e.message)  
            else throw e  
        }.getOrNull() ?: continue  
    }  
}
```

테스트 코드에서 무한한 입력 값이 있지 않았기 때문에 no line found는 `NoSuchElementException` 때문에 발생한 코드였고 while-try-catch에서도 처리한 부분이 없기 때문에 throw e 예외를 그대로 던지도록 구현했다.

즉, 처음 써봐서 헤멨던 부분은 
catch라는 네이밍 때문에 특정한 예외를 람다 안에서 바로 받을 수 있는줄 알았다는 것과
runCatching은 내부에 try-catch가 구현된 람다식이기 때문에 while을 종료하기 위한 break, continue 키워드를 사용할 수 없어 다시 throw e를 던져주어야 했다.
이 구현에 있어서는 while-try-catch 구문이 훨씬 덜 돌아가는 길이였다.

- - -
그렇다면 runCatchin은 어떤 이점을 가지고 있기에 try-catch 대신 코틀린에서 만들어진 것일까 ?
기본적으로 try-catch 구문에 비해 함수형에 체이닝 방식으로 처리가 간편하다.
getOrxxx 같은 편리한 함수와 recover 함수도 있다.(실패 값 다시 핸들링)

편리함 외에도 [toss tech](https://toss.tech/article/kotlin-result) 글을 읽어보면 Result를 반환하기 때문에 에러 처리를 원하는 클래스에 예외 처리를 강제하는 방식으로 사용이 가능하다. Result 객체로 반환하는 이유가 궁금했는데 역시 구현의 의미를 항시 생각하고 사용처를 고려해 보아야 한다.

- - - 
Footer. 학습하다 우연히 본 run을 prefix로 가지는 함수. 
[runs 블로그 번역](https://velog.io/@woga1999/Synchronous-and-Asynchronous-runs-run-runCatching-runBlocking-and-runInterruptible-in-Kotlin)
위 블로그에서 run,, runCatching, runBlocking, runInterruptible을 다룬다.
앞 두개는 동기, 뒤 두개는 비동기.

run은 스코프 함수. 항상 다른 스코프 함수와 헷갈렸는데 여러번 사용하다보니 점점 익숙해져 간다.
apply와 다르게 객체뿐만 아니라 여러 반환을 가질 수 있고, 또한 객체와 독립적으로 run {} 만 사용 가능.

runBlocking은 비동기 처리 예제에서 많이 봤는데, 역시나 예제, 테스트 코드, 메인 함수에서만 사용을 권장.

마지막 함수는 들어보지 못했으나 인지하다가 사용해볼 경우 찾아봐야겠다.